#VRML_SIM R2023b utf8
# license: Apache License 2.0
# license url: http://www.apache.org/licenses/LICENSE-2.0
# This is a proto file for Webots for the Aliengo
# Extracted from: D:/aliengo_sim2sim/protos/aliengo/urdf/aliengo.urdf

PROTO Aliengo [
  field  SFVec3f     translation     0 0 0
  field  SFRotation  rotation        0 0 1 0
  field  SFString    name            "Aliengo"  # Is `Robot.name`.
  field  SFString    controller      "void"     # Is `Robot.controller`.
  field  MFString    controllerArgs  []         # Is `Robot.controllerArgs`.
  field  SFString    customData      ""         # Is `Robot.customData`.
  field  SFBool      supervisor      FALSE      # Is `Robot.supervisor`.
  field  SFBool      synchronization TRUE       # Is `Robot.synchronization`.
  field  SFBool      selfCollision   FALSE      # Is `Robot.selfCollision`.
]
{
  Robot {
    translation IS translation
    rotation IS rotation
    controller IS controller
    controllerArgs IS controllerArgs
    customData IS customData
    supervisor IS supervisor
    synchronization IS synchronization
    selfCollision IS selfCollision
    children [
      Shape {
        appearance PBRAppearance {
          baseColor 0.500000 0.500000 0.500000
          roughness 1.000000
          metalness 0
        }
        geometry Box {
           size 0.001000 0.001000 0.001000
        }
      }
      Solid {
        children [
          DEF trunk_visual CadShape {
            url "../meshes/trunk.dae"
          }
          Solid {
            children [
              Shape {
                appearance DEF red PBRAppearance {
                  baseColor 0.500000 0.500000 0.500000
                  roughness 1.000000
                  metalness 0
                }
                geometry Box {
                   size 0.001000 0.001000 0.001000
                }
              }
            ]
            name "imu_link"
            boundingObject Box {
               size 0.001000 0.001000 0.001000
            }
            physics Physics {
              density -1
              mass 0.001000
              centerOfMass [ 0.000000 0.000000 0.000000 ]
              inertiaMatrix [
                1.000000e-04 1.000000e-06 1.000000e-04
                0.000000e+00 0.000000e+00 0.000000e+00
              ]
            }
          }
          HingeJoint {
            jointParameters HingeJointParameters {
              anchor 0.240700 -0.051000 0.000000
            }
            device [
              RotationalMotor {
                name "FR_hip_joint"
                maxVelocity 20.0
                minPosition -1.2217304763960306
                maxPosition 1.2217304763960306
                maxTorque 35.278
              }
              PositionSensor {
                name "FR_hip_joint_sensor"
              }
            ]
            endPoint Solid {
              translation 0.240700 -0.051000 0.000000
              children [
                Pose {
                  rotation 1.000000 0.000000 0.000000 3.141593
                  children [
                    DEF hip_visual CadShape {
                      url "../meshes/hip.dae"
                    }
                  ]
                }
                HingeJoint {
                  jointParameters HingeJointParameters {
                    axis 0.000000 1.000000 0.000000
                    anchor 0.000000 -0.086800 0.000000
                  }
                  device [
                    RotationalMotor {
                      name "FR_thigh_joint"
                      maxVelocity 20.0
                      minPosition -1.0471975512
                      maxPosition 4.18879020479
                      maxTorque 35.278
                    }
                    PositionSensor {
                      name "FR_thigh_joint_sensor"
                    }
                  ]
                  endPoint Solid {
                    translation 0.000000 -0.086800 0.000000
                    children [
                      DEF thigh_mirror_visual CadShape {
                        url "../meshes/thigh_mirror.dae"
                      }
                      HingeJoint {
                        jointParameters HingeJointParameters {
                          position -1.710423
                          axis 0.000000 1.000000 0.000000
                          anchor 0.000000 0.000000 -0.250000
                        }
                        device [
                          RotationalMotor {
                            name "FR_calf_joint"
                            maxVelocity 15.89
                            minPosition -2.775073510670984
                            maxPosition -0.6457718232379019
                            maxTorque 44.4
                          }
                          PositionSensor {
                            name "FR_calf_joint_sensor"
                          }
                        ]
                        endPoint Solid {
                          translation 0.000000 0.000000 -0.250000
                          rotation 0.000000 -1.000000 0.000000 1.710423
                          children [
                            DEF calf_visual CadShape {
                              url "../meshes/calf.dae"
                            }
                            Solid {
                              translation 0.000000 0.000000 -0.250000
                              children [
                                Shape {
                                  appearance DEF green PBRAppearance {
                                    baseColor 0.500000 0.500000 0.500000
                                    roughness 1.000000
                                    metalness 0
                                  }
                                  geometry Sphere {
                                    radius 0.0165
                                  }
                                }
                              ]
                              name "FR_foot"
                              boundingObject Sphere {
                                radius 0.0265
                              }
                              physics Physics {
                                density -1
                                mass 0.060000
                                centerOfMass [ 0.000000 0.000000 0.000000 ]
                                inertiaMatrix [
                                  1.685400e-05 1.685400e-05 1.685400e-05
                                  0.000000e+00 0.000000e+00 0.000000e+00
                                ]
                              }
                            }
                          ]
                          name "FR_calf"
                          boundingObject Pose {
                            translation 0.000000 0.000000 -0.125000
                            rotation 0.000000 1.000000 0.000000 1.570796
                            children [
                              Box {
                                 size 0.250000 0.020800 0.016000
                              }
                            ]
                          }
                          physics Physics {
                            density -1
                            mass 0.207000
                            centerOfMass [ 0.002781 0.000063 -0.142518 ]
                            inertiaMatrix [
                              2.129279e-03 2.141463e-03 3.758300e-05
                              3.900000e-08 5.757000e-06 -5.160000e-07
                            ]
                          }
                        }
                      }
                      Solid {
                        translation 0.000000 0.099700 0.000000
                        children [
                          Pose {
                            rotation 1.000000 0.000000 0.000000 1.570796
                            children [
                              Shape {
                                appearance USE green
                                geometry Cylinder {
                                  radius 0.035
                                  height 0.02
                                }
                              }
                            ]
                          }
                        ]
                        name "FR_calf_rotor"
                        boundingObject Pose {
                          rotation 1.000000 0.000000 0.000000 1.570796
                          children [
                            Cylinder {
                              radius 0.035
                              height 0.02
                            }
                          ]
                        }
                        physics Physics {
                          density -1
                          mass 0.132000
                          centerOfMass [ 0.000000 0.000000 0.000000 ]
                          inertiaMatrix [
                            1.454630e-04 1.330310e-04 1.454630e-04
                            0.000000e+00 0.000000e+00 0.000000e+00
                          ]
                        }
                      }
                    ]
                    name "FR_thigh"
                    boundingObject Pose {
                      translation 0.000000 0.000000 -0.125000
                      rotation 0.000000 1.000000 0.000000 1.570796
                      children [
                        Box {
                           size 0.250000 0.037400 0.043000
                        }
                      ]
                    }
                    physics Physics {
                      density -1
                      mass 0.639000
                      centerOfMass [ -0.005607 0.003877 -0.048199 ]
                      inertiaMatrix [
                        4.173855e-03 4.343802e-03 3.401360e-04
                        -1.028400e-05 -3.188740e-04 -1.092330e-04
                      ]
                    }
                  }
                }
                Solid {
                  translation 0.000000 -0.029800 0.000000
                  children [
                    Pose {
                      rotation 1.000000 0.000000 0.000000 1.570796
                      children [
                        Shape {
                          appearance USE green
                          geometry Cylinder {
                            radius 0.035
                            height 0.02
                          }
                        }
                      ]
                    }
                  ]
                  name "FR_thigh_rotor"
                  boundingObject Pose {
                    rotation 1.000000 0.000000 0.000000 1.570796
                    children [
                      Cylinder {
                        radius 0.035
                        height 0.02
                      }
                    ]
                  }
                  physics Physics {
                    density -1
                    mass 0.146000
                    centerOfMass [ 0.000000 0.000000 0.000000 ]
                    inertiaMatrix [
                      8.335200e-05 1.387020e-04 8.335200e-05
                      0.000000e+00 0.000000e+00 0.000000e+00
                    ]
                  }
                }
              ]
              name "FR_hip"
              boundingObject Pose {
                translation 0.000000 -0.083000 0.000000
                rotation 1.000000 0.000000 0.000000 1.570796
                children [
                  Cylinder {
                    radius 0.046
                    height 0.0418
                  }
                ]
              }
              physics Physics {
                density -1
                mass 1.993000
                centerOfMass [ -0.022191 -0.015144 -0.000015 ]
                inertiaMatrix [
                  2.446735e-03 3.925876e-03 4.148145e-03
                  5.980500e-04 1.945000e-06 -1.284000e-06
                ]
              }
            }
          }
          Solid {
            translation 0.139985 -0.051000 0.000000
            children [
              Pose {
                rotation 0.000000 1.000000 0.000000 1.570796
                children [
                  Shape {
                    appearance USE green
                    geometry Cylinder {
                      radius 0.035
                      height 0.02
                    }
                  }
                ]
              }
            ]
            name "FR_hip_rotor"
            boundingObject Pose {
              rotation 0.000000 1.000000 0.000000 1.570796
              children [
                Cylinder {
                  radius 0.035
                  height 0.02
                }
              ]
            }
            physics Physics {
              density -1
              mass 0.146000
              centerOfMass [ 0.000000 0.000000 0.000000 ]
              inertiaMatrix [
                1.387020e-04 8.335200e-05 8.335200e-05
                0.000000e+00 0.000000e+00 0.000000e+00
              ]
            }
          }
          HingeJoint {
            jointParameters HingeJointParameters {
              anchor 0.240700 0.051000 0.000000
            }
            device [
              RotationalMotor {
                name "FL_hip_joint"
                maxVelocity 20.0
                minPosition -1.2217304763960306
                maxPosition 1.2217304763960306
                maxTorque 35.278
              }
              PositionSensor {
                name "FL_hip_joint_sensor"
              }
            ]
            endPoint Solid {
              translation 0.240700 0.051000 0.000000
              children [
                USE hip_visual
                HingeJoint {
                  jointParameters HingeJointParameters {
                    axis 0.000000 1.000000 0.000000
                    anchor 0.000000 0.086800 0.000000
                  }
                  device [
                    RotationalMotor {
                      name "FL_thigh_joint"
                      maxVelocity 20.0
                      minPosition -1.0471975512
                      maxPosition 4.18879020479
                      maxTorque 35.278
                    }
                    PositionSensor {
                      name "FL_thigh_joint_sensor"
                    }
                  ]
                  endPoint Solid {
                    translation 0.000000 0.086800 0.000000
                    children [
                      DEF thigh_visual CadShape {
                        url "../meshes/thigh.dae"
                      }
                      HingeJoint {
                        jointParameters HingeJointParameters {
                          position -1.710423
                          axis 0.000000 1.000000 0.000000
                          anchor 0.000000 0.000000 -0.250000
                        }
                        device [
                          RotationalMotor {
                            name "FL_calf_joint"
                            maxVelocity 15.89
                            minPosition -2.775073510670984
                            maxPosition -0.6457718232379019
                            maxTorque 44.4
                          }
                          PositionSensor {
                            name "FL_calf_joint_sensor"
                          }
                        ]
                        endPoint Solid {
                          translation 0.000000 0.000000 -0.250000
                          rotation 0.000000 -1.000000 0.000000 1.710423
                          children [
                            USE calf_visual
                            Solid {
                              translation 0.000000 0.000000 -0.250000
                              children [
                                Shape {
                                  appearance USE green
                                  geometry Sphere {
                                    radius 0.0165
                                  }
                                }
                              ]
                              name "FL_foot"
                              boundingObject Sphere {
                                radius 0.0265
                              }
                              physics Physics {
                                density -1
                                mass 0.060000
                                centerOfMass [ 0.000000 0.000000 0.000000 ]
                                inertiaMatrix [
                                  1.685400e-05 1.685400e-05 1.685400e-05
                                  0.000000e+00 0.000000e+00 0.000000e+00
                                ]
                              }
                            }
                          ]
                          name "FL_calf"
                          boundingObject Pose {
                            translation 0.000000 0.000000 -0.125000
                            rotation 0.000000 1.000000 0.000000 1.570796
                            children [
                              Box {
                                 size 0.250000 0.020800 0.016000
                              }
                            ]
                          }
                          physics Physics {
                            density -1
                            mass 0.207000
                            centerOfMass [ 0.002781 0.000063 -0.142518 ]
                            inertiaMatrix [
                              2.129279e-03 2.141463e-03 3.758300e-05
                              3.900000e-08 5.757000e-06 -5.160000e-07
                            ]
                          }
                        }
                      }
                      Solid {
                        translation 0.000000 -0.099700 0.000000
                        children [
                          Pose {
                            rotation 1.000000 0.000000 0.000000 1.570796
                            children [
                              Shape {
                                appearance USE green
                                geometry Cylinder {
                                  radius 0.035
                                  height 0.02
                                }
                              }
                            ]
                          }
                        ]
                        name "FL_calf_rotor"
                        boundingObject Pose {
                          rotation 1.000000 0.000000 0.000000 1.570796
                          children [
                            Cylinder {
                              radius 0.035
                              height 0.02
                            }
                          ]
                        }
                        physics Physics {
                          density -1
                          mass 0.132000
                          centerOfMass [ 0.000000 0.000000 0.000000 ]
                          inertiaMatrix [
                            1.454630e-04 1.330310e-04 1.454630e-04
                            0.000000e+00 0.000000e+00 0.000000e+00
                          ]
                        }
                      }
                    ]
                    name "FL_thigh"
                    boundingObject Pose {
                      translation 0.000000 0.000000 -0.125000
                      rotation 0.000000 1.000000 0.000000 1.570796
                      children [
                        Box {
                           size 0.250000 0.037400 0.043000
                        }
                      ]
                    }
                    physics Physics {
                      density -1
                      mass 0.639000
                      centerOfMass [ -0.005607 -0.003877 -0.048199 ]
                      inertiaMatrix [
                        4.173855e-03 4.343802e-03 3.401360e-04
                        1.028400e-05 -3.188740e-04 1.092330e-04
                      ]
                    }
                  }
                }
                Solid {
                  translation 0.000000 0.029800 0.000000
                  children [
                    Pose {
                      rotation 1.000000 0.000000 0.000000 1.570796
                      children [
                        Shape {
                          appearance USE green
                          geometry Cylinder {
                            radius 0.035
                            height 0.02
                          }
                        }
                      ]
                    }
                  ]
                  name "FL_thigh_rotor"
                  boundingObject Pose {
                    rotation 1.000000 0.000000 0.000000 1.570796
                    children [
                      Cylinder {
                        radius 0.035
                        height 0.02
                      }
                    ]
                  }
                  physics Physics {
                    density -1
                    mass 0.146000
                    centerOfMass [ 0.000000 0.000000 0.000000 ]
                    inertiaMatrix [
                      8.335200e-05 1.387020e-04 8.335200e-05
                      0.000000e+00 0.000000e+00 0.000000e+00
                    ]
                  }
                }
              ]
              name "FL_hip"
              boundingObject Pose {
                translation 0.000000 0.083000 0.000000
                rotation 1.000000 0.000000 0.000000 1.570796
                children [
                  Cylinder {
                    radius 0.046
                    height 0.0418
                  }
                ]
              }
              physics Physics {
                density -1
                mass 1.993000
                centerOfMass [ -0.022191 0.015144 -0.000015 ]
                inertiaMatrix [
                  2.446735e-03 3.925876e-03 4.148145e-03
                  -5.980500e-04 1.945000e-06 1.284000e-06
                ]
              }
            }
          }
          Solid {
            translation 0.139985 0.051000 0.000000
            children [
              Pose {
                rotation 0.000000 1.000000 0.000000 1.570796
                children [
                  Shape {
                    appearance USE green
                    geometry Cylinder {
                      radius 0.035
                      height 0.02
                    }
                  }
                ]
              }
            ]
            name "FL_hip_rotor"
            boundingObject Pose {
              rotation 0.000000 1.000000 0.000000 1.570796
              children [
                Cylinder {
                  radius 0.035
                  height 0.02
                }
              ]
            }
            physics Physics {
              density -1
              mass 0.146000
              centerOfMass [ 0.000000 0.000000 0.000000 ]
              inertiaMatrix [
                1.387020e-04 8.335200e-05 8.335200e-05
                0.000000e+00 0.000000e+00 0.000000e+00
              ]
            }
          }
          HingeJoint {
            jointParameters HingeJointParameters {
              anchor -0.240700 -0.051000 0.000000
            }
            device [
              RotationalMotor {
                name "RR_hip_joint"
                maxVelocity 20.0
                minPosition -1.2217304763960306
                maxPosition 1.2217304763960306
                maxTorque 35.278
              }
              PositionSensor {
                name "RR_hip_joint_sensor"
              }
            ]
            endPoint Solid {
              translation -0.240700 -0.051000 0.000000
              children [
                Pose {
                  rotation 0.000000 0.000000 -1.000000 3.141593
                  children [
                    USE hip_visual
                  ]
                }
                HingeJoint {
                  jointParameters HingeJointParameters {
                    axis 0.000000 1.000000 0.000000
                    anchor 0.000000 -0.086800 0.000000
                  }
                  device [
                    RotationalMotor {
                      name "RR_thigh_joint"
                      maxVelocity 20.0
                      minPosition -1.0471975512
                      maxPosition 4.18879020479
                      maxTorque 35.278
                    }
                    PositionSensor {
                      name "RR_thigh_joint_sensor"
                    }
                  ]
                  endPoint Solid {
                    translation 0.000000 -0.086800 0.000000
                    children [
                      USE thigh_mirror_visual
                      HingeJoint {
                        jointParameters HingeJointParameters {
                          position -1.710423
                          axis 0.000000 1.000000 0.000000
                          anchor 0.000000 0.000000 -0.250000
                        }
                        device [
                          RotationalMotor {
                            name "RR_calf_joint"
                            maxVelocity 15.89
                            minPosition -2.775073510670984
                            maxPosition -0.6457718232379019
                            maxTorque 44.4
                          }
                          PositionSensor {
                            name "RR_calf_joint_sensor"
                          }
                        ]
                        endPoint Solid {
                          translation 0.000000 0.000000 -0.250000
                          rotation 0.000000 -1.000000 0.000000 1.710423
                          children [
                            USE calf_visual
                            Solid {
                              translation 0.000000 0.000000 -0.250000
                              children [
                                Shape {
                                  appearance USE green
                                  geometry Sphere {
                                    radius 0.0165
                                  }
                                }
                              ]
                              name "RR_foot"
                              boundingObject Sphere {
                                radius 0.0265
                              }
                              physics Physics {
                                density -1
                                mass 0.060000
                                centerOfMass [ 0.000000 0.000000 0.000000 ]
                                inertiaMatrix [
                                  1.685400e-05 1.685400e-05 1.685400e-05
                                  0.000000e+00 0.000000e+00 0.000000e+00
                                ]
                              }
                            }
                          ]
                          name "RR_calf"
                          boundingObject Pose {
                            translation 0.000000 0.000000 -0.125000
                            rotation 0.000000 1.000000 0.000000 1.570796
                            children [
                              Box {
                                 size 0.250000 0.020800 0.016000
                              }
                            ]
                          }
                          physics Physics {
                            density -1
                            mass 0.207000
                            centerOfMass [ 0.002781 0.000063 -0.142518 ]
                            inertiaMatrix [
                              2.129279e-03 2.141463e-03 3.758300e-05
                              3.900000e-08 5.757000e-06 -5.160000e-07
                            ]
                          }
                        }
                      }
                      Solid {
                        translation 0.000000 0.099700 0.000000
                        children [
                          Pose {
                            rotation 1.000000 0.000000 0.000000 1.570796
                            children [
                              Shape {
                                appearance USE green
                                geometry Cylinder {
                                  radius 0.035
                                  height 0.02
                                }
                              }
                            ]
                          }
                        ]
                        name "RR_calf_rotor"
                        boundingObject Pose {
                          rotation 1.000000 0.000000 0.000000 1.570796
                          children [
                            Cylinder {
                              radius 0.035
                              height 0.02
                            }
                          ]
                        }
                        physics Physics {
                          density -1
                          mass 0.132000
                          centerOfMass [ 0.000000 0.000000 0.000000 ]
                          inertiaMatrix [
                            1.454630e-04 1.330310e-04 1.454630e-04
                            0.000000e+00 0.000000e+00 0.000000e+00
                          ]
                        }
                      }
                    ]
                    name "RR_thigh"
                    boundingObject Pose {
                      translation 0.000000 0.000000 -0.125000
                      rotation 0.000000 1.000000 0.000000 1.570796
                      children [
                        Box {
                           size 0.250000 0.037400 0.043000
                        }
                      ]
                    }
                    physics Physics {
                      density -1
                      mass 0.639000
                      centerOfMass [ -0.005607 0.003877 -0.048199 ]
                      inertiaMatrix [
                        4.173855e-03 4.343802e-03 3.401360e-04
                        -1.028400e-05 -3.188740e-04 -1.092330e-04
                      ]
                    }
                  }
                }
                Solid {
                  translation 0.000000 -0.029800 0.000000
                  children [
                    Pose {
                      rotation 1.000000 0.000000 0.000000 1.570796
                      children [
                        Shape {
                          appearance USE green
                          geometry Cylinder {
                            radius 0.035
                            height 0.02
                          }
                        }
                      ]
                    }
                  ]
                  name "RR_thigh_rotor"
                  boundingObject Pose {
                    rotation 1.000000 0.000000 0.000000 1.570796
                    children [
                      Cylinder {
                        radius 0.035
                        height 0.02
                      }
                    ]
                  }
                  physics Physics {
                    density -1
                    mass 0.146000
                    centerOfMass [ 0.000000 0.000000 0.000000 ]
                    inertiaMatrix [
                      8.335200e-05 1.387020e-04 8.335200e-05
                      0.000000e+00 0.000000e+00 0.000000e+00
                    ]
                  }
                }
              ]
              name "RR_hip"
              boundingObject Pose {
                translation 0.000000 -0.083000 0.000000
                rotation 1.000000 0.000000 0.000000 1.570796
                children [
                  Cylinder {
                    radius 0.046
                    height 0.0418
                  }
                ]
              }
              physics Physics {
                density -1
                mass 1.993000
                centerOfMass [ 0.022191 -0.015144 -0.000015 ]
                inertiaMatrix [
                  2.446735e-03 3.925876e-03 4.148145e-03
                  -5.980500e-04 -1.945000e-06 -1.284000e-06
                ]
              }
            }
          }
          Solid {
            translation -0.139985 -0.051000 0.000000
            children [
              Pose {
                rotation 0.000000 1.000000 0.000000 1.570796
                children [
                  Shape {
                    appearance USE green
                    geometry Cylinder {
                      radius 0.035
                      height 0.02
                    }
                  }
                ]
              }
            ]
            name "RR_hip_rotor"
            boundingObject Pose {
              rotation 0.000000 1.000000 0.000000 1.570796
              children [
                Cylinder {
                  radius 0.035
                  height 0.02
                }
              ]
            }
            physics Physics {
              density -1
              mass 0.146000
              centerOfMass [ 0.000000 0.000000 0.000000 ]
              inertiaMatrix [
                1.387020e-04 8.335200e-05 8.335200e-05
                0.000000e+00 0.000000e+00 0.000000e+00
              ]
            }
          }
          HingeJoint {
            jointParameters HingeJointParameters {
              anchor -0.240700 0.051000 0.000000
            }
            device [
              RotationalMotor {
                name "RL_hip_joint"
                maxVelocity 20.0
                minPosition -1.2217304763960306
                maxPosition 1.2217304763960306
                maxTorque 35.278
              }
              PositionSensor {
                name "RL_hip_joint_sensor"
              }
            ]
            endPoint Solid {
              translation -0.240700 0.051000 0.000000
              children [
                Pose {
                  rotation 0.000000 1.000000 0.000000 3.141593
                  children [
                    USE hip_visual
                  ]
                }
                HingeJoint {
                  jointParameters HingeJointParameters {
                    axis 0.000000 1.000000 0.000000
                    anchor 0.000000 0.086800 0.000000
                  }
                  device [
                    RotationalMotor {
                      name "RL_thigh_joint"
                      maxVelocity 20.0
                      minPosition -1.0471975512
                      maxPosition 4.18879020479
                      maxTorque 35.278
                    }
                    PositionSensor {
                      name "RL_thigh_joint_sensor"
                    }
                  ]
                  endPoint Solid {
                    translation 0.000000 0.086800 0.000000
                    children [
                      USE thigh_visual
                      HingeJoint {
                        jointParameters HingeJointParameters {
                          position -1.710423
                          axis 0.000000 1.000000 0.000000
                          anchor 0.000000 0.000000 -0.250000
                        }
                        device [
                          RotationalMotor {
                            name "RL_calf_joint"
                            maxVelocity 15.89
                            minPosition -2.775073510670984
                            maxPosition -0.6457718232379019
                            maxTorque 44.4
                          }
                          PositionSensor {
                            name "RL_calf_joint_sensor"
                          }
                        ]
                        endPoint Solid {
                          translation 0.000000 0.000000 -0.250000
                          rotation 0.000000 -1.000000 0.000000 1.710423
                          children [
                            USE calf_visual
                            Solid {
                              translation 0.000000 0.000000 -0.250000
                              children [
                                Shape {
                                  appearance USE green
                                  geometry Sphere {
                                    radius 0.0165
                                  }
                                }
                              ]
                              name "RL_foot"
                              boundingObject Sphere {
                                radius 0.0265
                              }
                              physics Physics {
                                density -1
                                mass 0.060000
                                centerOfMass [ 0.000000 0.000000 0.000000 ]
                                inertiaMatrix [
                                  1.685400e-05 1.685400e-05 1.685400e-05
                                  0.000000e+00 0.000000e+00 0.000000e+00
                                ]
                              }
                            }
                          ]
                          name "RL_calf"
                          boundingObject Pose {
                            translation 0.000000 0.000000 -0.125000
                            rotation 0.000000 1.000000 0.000000 1.570796
                            children [
                              Box {
                                 size 0.250000 0.020800 0.016000
                              }
                            ]
                          }
                          physics Physics {
                            density -1
                            mass 0.207000
                            centerOfMass [ 0.002781 0.000063 -0.142518 ]
                            inertiaMatrix [
                              2.129279e-03 2.141463e-03 3.758300e-05
                              3.900000e-08 5.757000e-06 -5.160000e-07
                            ]
                          }
                        }
                      }
                      Solid {
                        translation 0.000000 -0.099700 0.000000
                        children [
                          Pose {
                            rotation 1.000000 0.000000 0.000000 1.570796
                            children [
                              Shape {
                                appearance USE green
                                geometry Cylinder {
                                  radius 0.035
                                  height 0.02
                                }
                              }
                            ]
                          }
                        ]
                        name "RL_calf_rotor"
                        boundingObject Pose {
                          rotation 1.000000 0.000000 0.000000 1.570796
                          children [
                            Cylinder {
                              radius 0.035
                              height 0.02
                            }
                          ]
                        }
                        physics Physics {
                          density -1
                          mass 0.132000
                          centerOfMass [ 0.000000 0.000000 0.000000 ]
                          inertiaMatrix [
                            1.454630e-04 1.330310e-04 1.454630e-04
                            0.000000e+00 0.000000e+00 0.000000e+00
                          ]
                        }
                      }
                    ]
                    name "RL_thigh"
                    boundingObject Pose {
                      translation 0.000000 0.000000 -0.125000
                      rotation 0.000000 1.000000 0.000000 1.570796
                      children [
                        Box {
                           size 0.250000 0.037400 0.043000
                        }
                      ]
                    }
                    physics Physics {
                      density -1
                      mass 0.639000
                      centerOfMass [ -0.005607 -0.003877 -0.048199 ]
                      inertiaMatrix [
                        4.173855e-03 4.343802e-03 3.401360e-04
                        1.028400e-05 -3.188740e-04 1.092330e-04
                      ]
                    }
                  }
                }
                Solid {
                  translation 0.000000 0.029800 0.000000
                  children [
                    Pose {
                      rotation 1.000000 0.000000 0.000000 1.570796
                      children [
                        Shape {
                          appearance USE green
                          geometry Cylinder {
                            radius 0.035
                            height 0.02
                          }
                        }
                      ]
                    }
                  ]
                  name "RL_thigh_rotor"
                  boundingObject Pose {
                    rotation 1.000000 0.000000 0.000000 1.570796
                    children [
                      Cylinder {
                        radius 0.035
                        height 0.02
                      }
                    ]
                  }
                  physics Physics {
                    density -1
                    mass 0.146000
                    centerOfMass [ 0.000000 0.000000 0.000000 ]
                    inertiaMatrix [
                      8.335200e-05 1.387020e-04 8.335200e-05
                      0.000000e+00 0.000000e+00 0.000000e+00
                    ]
                  }
                }
              ]
              name "RL_hip"
              boundingObject Pose {
                translation 0.000000 0.083000 0.000000
                rotation 1.000000 0.000000 0.000000 1.570796
                children [
                  Cylinder {
                    radius 0.046
                    height 0.0418
                  }
                ]
              }
              physics Physics {
                density -1
                mass 1.993000
                centerOfMass [ 0.022191 0.015144 -0.000015 ]
                inertiaMatrix [
                  2.446735e-03 3.925876e-03 4.148145e-03
                  5.980500e-04 -1.945000e-06 1.284000e-06
                ]
              }
            }
          }
          Solid {
            translation -0.139985 0.051000 0.000000
            children [
              Pose {
                rotation 0.000000 1.000000 0.000000 1.570796
                children [
                  Shape {
                    appearance USE green
                    geometry Cylinder {
                      radius 0.035
                      height 0.02
                    }
                  }
                ]
              }
            ]
            name "RL_hip_rotor"
            boundingObject Pose {
              rotation 0.000000 1.000000 0.000000 1.570796
              children [
                Cylinder {
                  radius 0.035
                  height 0.02
                }
              ]
            }
            physics Physics {
              density -1
              mass 0.146000
              centerOfMass [ 0.000000 0.000000 0.000000 ]
              inertiaMatrix [
                1.387020e-04 8.335200e-05 8.335200e-05
                0.000000e+00 0.000000e+00 0.000000e+00
              ]
            }
          }
        ]
        name "trunk"
        boundingObject Box {
           size 0.647000 0.150000 0.112000
        }
        physics Physics {
          density -1
          mass 11.644000
          centerOfMass [ 0.008811 0.003839 0.000273 ]
          inertiaMatrix [
            5.194489e-02 2.469392e-01 2.709483e-01
            1.703617e-03 2.359410e-04 1.197830e-04
          ]
        }
      }
    ]
    name IS name
  }
}
