#VRML_SIM R2023b utf8

EXTERNPROTO "https://raw.githubusercontent.com/cyberbotics/webots/R2023b/projects/objects/backgrounds/protos/TexturedBackground.proto"
EXTERNPROTO "https://raw.githubusercontent.com/cyberbotics/webots/R2023b/projects/objects/backgrounds/protos/TexturedBackgroundLight.proto"
EXTERNPROTO "https://raw.githubusercontent.com/cyberbotics/webots/R2023b/projects/objects/floors/protos/RectangleArena.proto"

WorldInfo {
  basicTimeStep 1
  FPS 30
}
Viewpoint {
  orientation 0.07328818146014643 -0.07266185274950328 -0.9946602925689124 4.4818890143393855
  position 1.5987840570663 -17.77838496145989 1.2965763091990055
}
TexturedBackground {
}
TexturedBackgroundLight {
}
RectangleArena {
  floorSize 10 30
}
DEF Aliengo Robot {
  translation 0.0100506 -14.09 0.37
  rotation 0 0 1 1.5708
  children [
    InertialUnit {
      name "IMU"
    }
    Accelerometer {
    }
    Gyro {
    }
    DEF trunk_visual CadShape {
      url [
        "../protos/meshes/trunk.dae"
      ]
    }
    Solid {
      children [
        Shape {
          appearance DEF red PBRAppearance {
            baseColor 0.5 0.5 0.5
            roughness 1
            metalness 0
          }
          geometry Box {
            size 0.001 0.001 0.001
          }
        }
      ]
      name "imu_link"
      boundingObject Box {
        size 0.001 0.001 0.001
      }
      physics Physics {
        density -1
        mass 0.001
        centerOfMass [
          0 0 0
        ]
        inertiaMatrix [
          0.0001 1e-06 0.0001
          0 0 0
        ]
      }
    }
    HingeJoint {
      jointParameters HingeJointParameters {
        position -0.1
        anchor 0.2407 -0.051 0
      }
      device [
        RotationalMotor {
          name "FR_hip_joint"
          maxVelocity 20
          minPosition -1.2217304763960306
          maxPosition 1.2217304763960306
          maxTorque 35.278
        }
        PositionSensor {
          name "FR_hip_joint_sensor"
        }
      ]
      endPoint Solid {
        translation 0.2407 -0.051 0
        rotation -1 0 0 0.09999999999999855
        children [
          Pose {
            rotation 1 0 0 3.141593
            children [
              DEF hip_visual CadShape {
                url [
                  "../protos/meshes/hip.dae"
                ]
              }
            ]
          }
          HingeJoint {
            jointParameters HingeJointParameters {
              position 0.7854
              axis 0 1 0
              anchor 0 -0.0868 0
            }
            device [
              RotationalMotor {
                name "FR_thigh_joint"
                maxVelocity 20
                minPosition -1.0471975512
                maxPosition 4.18879020479
                maxTorque 35.278
              }
              PositionSensor {
                name "FR_thigh_joint_sensor"
              }
            ]
            endPoint Solid {
              translation 0 -0.0868 0
              rotation 0 1 0 0.7854000000000001
              children [
                DEF thigh_mirror_visual CadShape {
                  url [
                    "../protos/meshes/thigh_mirror.dae"
                  ]
                }
                HingeJoint {
                  jointParameters HingeJointParameters {
                    position -1.5708
                    axis 0 1 0
                    anchor 0 0 -0.25
                  }
                  device [
                    RotationalMotor {
                      name "FR_calf_joint"
                      maxVelocity 15.89
                      minPosition -2.775073510670984
                      maxPosition -0.6457718232379019
                      maxTorque 44.4
                    }
                    PositionSensor {
                      name "FR_calf_joint_sensor"
                    }
                  ]
                  endPoint Solid {
                    translation 0 0 -0.25
                    rotation 0 -1 0 1.5708
                    children [
                      DEF calf_visual CadShape {
                        url [
                          "../protos/meshes/calf.dae"
                        ]
                      }
                      Solid {
                        translation 0 0 -0.25
                        children [
                          Shape {
                            appearance DEF green PBRAppearance {
                              baseColor 0.5 0.5 0.5
                              roughness 1
                              metalness 0
                            }
                            geometry Sphere {
                              radius 0.0165
                            }
                          }
                        ]
                        name "FR_foot"
                        boundingObject Sphere {
                          radius 0.0265
                        }
                        physics Physics {
                          density -1
                          mass 0.06
                          centerOfMass [
                            0 0 0
                          ]
                          inertiaMatrix [
                            1.6854e-05 1.6854e-05 1.6854e-05
                            0 0 0
                          ]
                        }
                      }
                    ]
                    name "FR_calf"
                    boundingObject Pose {
                      translation 0 0 -0.125
                      rotation 0 1 0 1.570796
                      children [
                        Box {
                          size 0.25 0.0208 0.016
                        }
                      ]
                    }
                    physics Physics {
                      density -1
                      mass 0.207
                      centerOfMass [
                        0.002781 6.3e-05 -0.142518
                      ]
                      inertiaMatrix [
                        0.002129279 0.002141463 3.7583e-05
                        3.9e-08 5.757e-06 -5.16e-07
                      ]
                    }
                  }
                }
                Solid {
                  translation 0 0.0997 0
                  children [
                    Pose {
                      rotation 1 0 0 1.570796
                      children [
                        Shape {
                          appearance USE green
                          geometry Cylinder {
                            height 0.02
                            radius 0.035
                          }
                        }
                      ]
                    }
                  ]
                  name "FR_calf_rotor"
                  boundingObject Pose {
                    rotation 1 0 0 1.570796
                    children [
                      Cylinder {
                        height 0.02
                        radius 0.035
                      }
                    ]
                  }
                  physics Physics {
                    density -1
                    mass 0.132
                    centerOfMass [
                      0 0 0
                    ]
                    inertiaMatrix [
                      0.000145463 0.000133031 0.000145463
                      0 0 0
                    ]
                  }
                }
              ]
              name "FR_thigh"
              boundingObject Pose {
                translation 0 0 -0.125
                rotation 0 1 0 1.570796
                children [
                  Box {
                    size 0.25 0.0374 0.043
                  }
                ]
              }
              physics Physics {
                density -1
                mass 0.639
                centerOfMass [
                  -0.005607 0.003877 -0.048199
                ]
                inertiaMatrix [
                  0.004173855 0.004343802 0.000340136
                  -1.0284e-05 -0.000318874 -0.000109233
                ]
              }
            }
          }
          Solid {
            translation 0 -0.0298 0
            children [
              Pose {
                rotation 1 0 0 1.570796
                children [
                  Shape {
                    appearance USE green
                    geometry Cylinder {
                      height 0.02
                      radius 0.035
                    }
                  }
                ]
              }
            ]
            name "FR_thigh_rotor"
            boundingObject Pose {
              rotation 1 0 0 1.570796
              children [
                Cylinder {
                  height 0.02
                  radius 0.035
                }
              ]
            }
            physics Physics {
              density -1
              mass 0.146
              centerOfMass [
                0 0 0
              ]
              inertiaMatrix [
                8.3352e-05 0.000138702 8.3352e-05
                0 0 0
              ]
            }
          }
        ]
        name "FR_hip"
        boundingObject Pose {
          translation 0 -0.083 0
          rotation 1 0 0 1.570796
          children [
            Cylinder {
              height 0.0418
              radius 0.046
            }
          ]
        }
        physics Physics {
          density -1
          mass 1.993
          centerOfMass [
            -0.022191 -0.015144 -1.5e-05
          ]
          inertiaMatrix [
            0.002446735 0.003925876 0.004148145
            0.00059805 1.945e-06 -1.284e-06
          ]
        }
      }
    }
    Solid {
      translation 0.139985 -0.051 0
      children [
        Pose {
          rotation 0 1 0 1.570796
          children [
            Shape {
              appearance USE green
              geometry Cylinder {
                height 0.02
                radius 0.035
              }
            }
          ]
        }
      ]
      name "FR_hip_rotor"
      boundingObject Pose {
        rotation 0 1 0 1.570796
        children [
          Cylinder {
            height 0.02
            radius 0.035
          }
        ]
      }
      physics Physics {
        density -1
        mass 0.146
        centerOfMass [
          0 0 0
        ]
        inertiaMatrix [
          0.000138702 8.3352e-05 8.3352e-05
          0 0 0
        ]
      }
    }
    HingeJoint {
      jointParameters HingeJointParameters {
        position 0.1
        anchor 0.2407 0.051 0
      }
      device [
        RotationalMotor {
          name "FL_hip_joint"
          maxVelocity 20
          minPosition -1.2217304763960306
          maxPosition 1.2217304763960306
          maxTorque 35.278
        }
        PositionSensor {
          name "FL_hip_joint_sensor"
        }
      ]
      endPoint Solid {
        translation 0.2407 0.051 0
        rotation 1 0 0 0.09999999999999855
        children [
          USE hip_visual
          HingeJoint {
            jointParameters HingeJointParameters {
              position 0.7854
              axis 0 1 0
              anchor 0 0.0868 0
            }
            device [
              RotationalMotor {
                name "FL_thigh_joint"
                maxVelocity 20
                minPosition -1.0471975512
                maxPosition 4.18879020479
                maxTorque 35.278
              }
              PositionSensor {
                name "FL_thigh_joint_sensor"
              }
            ]
            endPoint Solid {
              translation 0 0.0868 0
              rotation 0 1 0 0.7854000000000001
              children [
                DEF thigh_visual CadShape {
                  url [
                    "../protos/meshes/thigh.dae"
                  ]
                }
                HingeJoint {
                  jointParameters HingeJointParameters {
                    position -1.5708
                    axis 0 1 0
                    anchor 0 0 -0.25
                  }
                  device [
                    RotationalMotor {
                      name "FL_calf_joint"
                      maxVelocity 15.89
                      minPosition -2.775073510670984
                      maxPosition -0.6457718232379019
                      maxTorque 44.4
                    }
                    PositionSensor {
                      name "FL_calf_joint_sensor"
                    }
                  ]
                  endPoint Solid {
                    translation 0 0 -0.25
                    rotation 0 -1 0 1.5708
                    children [
                      USE calf_visual
                      Solid {
                        translation 0 0 -0.25
                        children [
                          Shape {
                            appearance USE green
                            geometry Sphere {
                              radius 0.0165
                            }
                          }
                        ]
                        name "FL_foot"
                        boundingObject Sphere {
                          radius 0.0265
                        }
                        physics Physics {
                          density -1
                          mass 0.06
                          centerOfMass [
                            0 0 0
                          ]
                          inertiaMatrix [
                            1.6854e-05 1.6854e-05 1.6854e-05
                            0 0 0
                          ]
                        }
                      }
                    ]
                    name "FL_calf"
                    boundingObject Pose {
                      translation 0 0 -0.125
                      rotation 0 1 0 1.570796
                      children [
                        Box {
                          size 0.25 0.0208 0.016
                        }
                      ]
                    }
                    physics Physics {
                      density -1
                      mass 0.207
                      centerOfMass [
                        0.002781 6.3e-05 -0.142518
                      ]
                      inertiaMatrix [
                        0.002129279 0.002141463 3.7583e-05
                        3.9e-08 5.757e-06 -5.16e-07
                      ]
                    }
                  }
                }
                Solid {
                  translation 0 -0.0997 0
                  children [
                    Pose {
                      rotation 1 0 0 1.570796
                      children [
                        Shape {
                          appearance USE green
                          geometry Cylinder {
                            height 0.02
                            radius 0.035
                          }
                        }
                      ]
                    }
                  ]
                  name "FL_calf_rotor"
                  boundingObject Pose {
                    rotation 1 0 0 1.570796
                    children [
                      Cylinder {
                        height 0.02
                        radius 0.035
                      }
                    ]
                  }
                  physics Physics {
                    density -1
                    mass 0.132
                    centerOfMass [
                      0 0 0
                    ]
                    inertiaMatrix [
                      0.000145463 0.000133031 0.000145463
                      0 0 0
                    ]
                  }
                }
              ]
              name "FL_thigh"
              boundingObject Pose {
                translation 0 0 -0.125
                rotation 0 1 0 1.570796
                children [
                  Box {
                    size 0.25 0.0374 0.043
                  }
                ]
              }
              physics Physics {
                density -1
                mass 0.639
                centerOfMass [
                  -0.005607 -0.003877 -0.048199
                ]
                inertiaMatrix [
                  0.004173855 0.004343802 0.000340136
                  1.0284e-05 -0.000318874 0.000109233
                ]
              }
            }
          }
          Solid {
            translation 0 0.0298 0
            children [
              Pose {
                rotation 1 0 0 1.570796
                children [
                  Shape {
                    appearance USE green
                    geometry Cylinder {
                      height 0.02
                      radius 0.035
                    }
                  }
                ]
              }
            ]
            name "FL_thigh_rotor"
            boundingObject Pose {
              rotation 1 0 0 1.570796
              children [
                Cylinder {
                  height 0.02
                  radius 0.035
                }
              ]
            }
            physics Physics {
              density -1
              mass 0.146
              centerOfMass [
                0 0 0
              ]
              inertiaMatrix [
                8.3352e-05 0.000138702 8.3352e-05
                0 0 0
              ]
            }
          }
        ]
        name "FL_hip"
        boundingObject Pose {
          translation 0 0.083 0
          rotation 1 0 0 1.570796
          children [
            Cylinder {
              height 0.0418
              radius 0.046
            }
          ]
        }
        physics Physics {
          density -1
          mass 1.993
          centerOfMass [
            -0.022191 0.015144 -1.5e-05
          ]
          inertiaMatrix [
            0.002446735 0.003925876 0.004148145
            -0.00059805 1.945e-06 1.284e-06
          ]
        }
      }
    }
    Solid {
      translation 0.139985 0.051 0
      children [
        Pose {
          rotation 0 1 0 1.570796
          children [
            Shape {
              appearance USE green
              geometry Cylinder {
                height 0.02
                radius 0.035
              }
            }
          ]
        }
      ]
      name "FL_hip_rotor"
      boundingObject Pose {
        rotation 0 1 0 1.570796
        children [
          Cylinder {
            height 0.02
            radius 0.035
          }
        ]
      }
      physics Physics {
        density -1
        mass 0.146
        centerOfMass [
          0 0 0
        ]
        inertiaMatrix [
          0.000138702 8.3352e-05 8.3352e-05
          0 0 0
        ]
      }
    }
    HingeJoint {
      jointParameters HingeJointParameters {
        position -0.1
        anchor -0.2407 -0.051 0
      }
      device [
        RotationalMotor {
          name "RR_hip_joint"
          maxVelocity 20
          minPosition -1.2217304763960306
          maxPosition 1.2217304763960306
          maxTorque 35.278
        }
        PositionSensor {
          name "RR_hip_joint_sensor"
        }
      ]
      endPoint Solid {
        translation -0.2407 -0.051 0
        rotation -1 0 0 0.09999999999999855
        children [
          Pose {
            rotation 0 0 -1 3.141593
            children [
              USE hip_visual
            ]
          }
          HingeJoint {
            jointParameters HingeJointParameters {
              position 0.7854
              axis 0 1 0
              anchor 0 -0.0868 0
            }
            device [
              RotationalMotor {
                name "RR_thigh_joint"
                maxVelocity 20
                minPosition -1.0471975512
                maxPosition 4.18879020479
                maxTorque 35.278
              }
              PositionSensor {
                name "RR_thigh_joint_sensor"
              }
            ]
            endPoint Solid {
              translation 0 -0.0868 0
              rotation 0 1 0 0.7854000000000001
              children [
                USE thigh_mirror_visual
                HingeJoint {
                  jointParameters HingeJointParameters {
                    position -1.5708
                    axis 0 1 0
                    anchor 0 0 -0.25
                  }
                  device [
                    RotationalMotor {
                      name "RR_calf_joint"
                      maxVelocity 15.89
                      minPosition -2.775073510670984
                      maxPosition -0.6457718232379019
                      maxTorque 44.4
                    }
                    PositionSensor {
                      name "RR_calf_joint_sensor"
                    }
                  ]
                  endPoint Solid {
                    translation 0 0 -0.25
                    rotation 0 -1 0 1.5708
                    children [
                      USE calf_visual
                      Solid {
                        translation 0 0 -0.25
                        children [
                          Shape {
                            appearance USE green
                            geometry Sphere {
                              radius 0.0165
                            }
                          }
                        ]
                        name "RR_foot"
                        boundingObject Sphere {
                          radius 0.0265
                        }
                        physics Physics {
                          density -1
                          mass 0.06
                          centerOfMass [
                            0 0 0
                          ]
                          inertiaMatrix [
                            1.6854e-05 1.6854e-05 1.6854e-05
                            0 0 0
                          ]
                        }
                      }
                    ]
                    name "RR_calf"
                    boundingObject Pose {
                      translation 0 0 -0.125
                      rotation 0 1 0 1.570796
                      children [
                        Box {
                          size 0.25 0.0208 0.016
                        }
                      ]
                    }
                    physics Physics {
                      density -1
                      mass 0.207
                      centerOfMass [
                        0.002781 6.3e-05 -0.142518
                      ]
                      inertiaMatrix [
                        0.002129279 0.002141463 3.7583e-05
                        3.9e-08 5.757e-06 -5.16e-07
                      ]
                    }
                  }
                }
                Solid {
                  translation 0 0.0997 0
                  children [
                    Pose {
                      rotation 1 0 0 1.570796
                      children [
                        Shape {
                          appearance USE green
                          geometry Cylinder {
                            height 0.02
                            radius 0.035
                          }
                        }
                      ]
                    }
                  ]
                  name "RR_calf_rotor"
                  boundingObject Pose {
                    rotation 1 0 0 1.570796
                    children [
                      Cylinder {
                        height 0.02
                        radius 0.035
                      }
                    ]
                  }
                  physics Physics {
                    density -1
                    mass 0.132
                    centerOfMass [
                      0 0 0
                    ]
                    inertiaMatrix [
                      0.000145463 0.000133031 0.000145463
                      0 0 0
                    ]
                  }
                }
              ]
              name "RR_thigh"
              boundingObject Pose {
                translation 0 0 -0.125
                rotation 0 1 0 1.570796
                children [
                  Box {
                    size 0.25 0.0374 0.043
                  }
                ]
              }
              physics Physics {
                density -1
                mass 0.639
                centerOfMass [
                  -0.005607 0.003877 -0.048199
                ]
                inertiaMatrix [
                  0.004173855 0.004343802 0.000340136
                  -1.0284e-05 -0.000318874 -0.000109233
                ]
              }
            }
          }
          Solid {
            translation 0 -0.0298 0
            children [
              Pose {
                rotation 1 0 0 1.570796
                children [
                  Shape {
                    appearance USE green
                    geometry Cylinder {
                      height 0.02
                      radius 0.035
                    }
                  }
                ]
              }
            ]
            name "RR_thigh_rotor"
            boundingObject Pose {
              rotation 1 0 0 1.570796
              children [
                Cylinder {
                  height 0.02
                  radius 0.035
                }
              ]
            }
            physics Physics {
              density -1
              mass 0.146
              centerOfMass [
                0 0 0
              ]
              inertiaMatrix [
                8.3352e-05 0.000138702 8.3352e-05
                0 0 0
              ]
            }
          }
        ]
        name "RR_hip"
        boundingObject Pose {
          translation 0 -0.083 0
          rotation 1 0 0 1.570796
          children [
            Cylinder {
              height 0.0418
              radius 0.046
            }
          ]
        }
        physics Physics {
          density -1
          mass 1.993
          centerOfMass [
            0.022191 -0.015144 -1.5e-05
          ]
          inertiaMatrix [
            0.002446735 0.003925876 0.004148145
            -0.00059805 -1.945e-06 -1.284e-06
          ]
        }
      }
    }
    Solid {
      translation -0.139985 -0.051 0
      children [
        Pose {
          rotation 0 1 0 1.570796
          children [
            Shape {
              appearance USE green
              geometry Cylinder {
                height 0.02
                radius 0.035
              }
            }
          ]
        }
      ]
      name "RR_hip_rotor"
      boundingObject Pose {
        rotation 0 1 0 1.570796
        children [
          Cylinder {
            height 0.02
            radius 0.035
          }
        ]
      }
      physics Physics {
        density -1
        mass 0.146
        centerOfMass [
          0 0 0
        ]
        inertiaMatrix [
          0.000138702 8.3352e-05 8.3352e-05
          0 0 0
        ]
      }
    }
    HingeJoint {
      jointParameters HingeJointParameters {
        position 0.1
        anchor -0.2407 0.051 0
      }
      device [
        RotationalMotor {
          name "RL_hip_joint"
          maxVelocity 20
          minPosition -1.2217304763960306
          maxPosition 1.2217304763960306
          maxTorque 35.278
        }
        PositionSensor {
          name "RL_hip_joint_sensor"
        }
      ]
      endPoint Solid {
        translation -0.2407 0.051 0
        rotation 1 0 0 0.09999999999999855
        children [
          Pose {
            rotation 0 1 0 3.141593
            children [
              USE hip_visual
            ]
          }
          HingeJoint {
            jointParameters HingeJointParameters {
              position 0.7854
              axis 0 1 0
              anchor 0 0.0868 0
            }
            device [
              RotationalMotor {
                name "RL_thigh_joint"
                maxVelocity 20
                minPosition -1.0471975512
                maxPosition 4.18879020479
                maxTorque 35.278
              }
              PositionSensor {
                name "RL_thigh_joint_sensor"
              }
            ]
            endPoint Solid {
              translation 0 0.0868 0
              rotation 0 1 0 0.7854000000000001
              children [
                USE thigh_visual
                HingeJoint {
                  jointParameters HingeJointParameters {
                    position -1.5708
                    axis 0 1 0
                    anchor 0 0 -0.25
                  }
                  device [
                    RotationalMotor {
                      name "RL_calf_joint"
                      maxVelocity 15.89
                      minPosition -2.775073510670984
                      maxPosition -0.6457718232379019
                      maxTorque 44.4
                    }
                    PositionSensor {
                      name "RL_calf_joint_sensor"
                    }
                  ]
                  endPoint Solid {
                    translation 0 0 -0.25
                    rotation 0 -1 0 1.5708
                    children [
                      USE calf_visual
                      Solid {
                        translation 0 0 -0.25
                        children [
                          Shape {
                            appearance USE green
                            geometry Sphere {
                              radius 0.0165
                            }
                          }
                        ]
                        name "RL_foot"
                        boundingObject Sphere {
                          radius 0.0265
                        }
                        physics Physics {
                          density -1
                          mass 0.06
                          centerOfMass [
                            0 0 0
                          ]
                          inertiaMatrix [
                            1.6854e-05 1.6854e-05 1.6854e-05
                            0 0 0
                          ]
                        }
                      }
                    ]
                    name "RL_calf"
                    boundingObject Pose {
                      translation 0 0 -0.125
                      rotation 0 1 0 1.570796
                      children [
                        Box {
                          size 0.25 0.0208 0.016
                        }
                      ]
                    }
                    physics Physics {
                      density -1
                      mass 0.207
                      centerOfMass [
                        0.002781 6.3e-05 -0.142518
                      ]
                      inertiaMatrix [
                        0.002129279 0.002141463 3.7583e-05
                        3.9e-08 5.757e-06 -5.16e-07
                      ]
                    }
                  }
                }
                Solid {
                  translation 0 -0.0997 0
                  children [
                    Pose {
                      rotation 1 0 0 1.570796
                      children [
                        Shape {
                          appearance USE green
                          geometry Cylinder {
                            height 0.02
                            radius 0.035
                          }
                        }
                      ]
                    }
                  ]
                  name "RL_calf_rotor"
                  boundingObject Pose {
                    rotation 1 0 0 1.570796
                    children [
                      Cylinder {
                        height 0.02
                        radius 0.035
                      }
                    ]
                  }
                  physics Physics {
                    density -1
                    mass 0.132
                    centerOfMass [
                      0 0 0
                    ]
                    inertiaMatrix [
                      0.000145463 0.000133031 0.000145463
                      0 0 0
                    ]
                  }
                }
              ]
              name "RL_thigh"
              boundingObject Pose {
                translation 0 0 -0.125
                rotation 0 1 0 1.570796
                children [
                  Box {
                    size 0.25 0.0374 0.043
                  }
                ]
              }
              physics Physics {
                density -1
                mass 0.639
                centerOfMass [
                  -0.005607 -0.003877 -0.048199
                ]
                inertiaMatrix [
                  0.004173855 0.004343802 0.000340136
                  1.0284e-05 -0.000318874 0.000109233
                ]
              }
            }
          }
          Solid {
            translation 0 0.0298 0
            children [
              Pose {
                rotation 1 0 0 1.570796
                children [
                  Shape {
                    appearance USE green
                    geometry Cylinder {
                      height 0.02
                      radius 0.035
                    }
                  }
                ]
              }
            ]
            name "RL_thigh_rotor"
            boundingObject Pose {
              rotation 1 0 0 1.570796
              children [
                Cylinder {
                  height 0.02
                  radius 0.035
                }
              ]
            }
            physics Physics {
              density -1
              mass 0.146
              centerOfMass [
                0 0 0
              ]
              inertiaMatrix [
                8.3352e-05 0.000138702 8.3352e-05
                0 0 0
              ]
            }
          }
        ]
        name "RL_hip"
        boundingObject Pose {
          translation 0 0.083 0
          rotation 1 0 0 1.570796
          children [
            Cylinder {
              height 0.0418
              radius 0.046
            }
          ]
        }
        physics Physics {
          density -1
          mass 1.993
          centerOfMass [
            0.022191 0.015144 -1.5e-05
          ]
          inertiaMatrix [
            0.002446735 0.003925876 0.004148145
            0.00059805 -1.945e-06 1.284e-06
          ]
        }
      }
    }
    Solid {
      translation -0.139985 0.051 0
      children [
        Pose {
          rotation 0 1 0 1.570796
          children [
            Shape {
              appearance USE green
              geometry Cylinder {
                height 0.02
                radius 0.035
              }
            }
          ]
        }
      ]
      name "RL_hip_rotor"
      boundingObject Pose {
        rotation 0 1 0 1.570796
        children [
          Cylinder {
            height 0.02
            radius 0.035
          }
        ]
      }
      physics Physics {
        density -1
        mass 0.146
        centerOfMass [
          0 0 0
        ]
        inertiaMatrix [
          0.000138702 8.3352e-05 8.3352e-05
          0 0 0
        ]
      }
    }
  ]
  name "Aliengo"
  boundingObject Box {
    size 0.647 0.15 0.112
  }
  physics Physics {
    density -1
    mass 11.644
    centerOfMass [
      0.008811 0.003839 0.000273
    ]
    inertiaMatrix [
      0.05194489 0.2469392 0.2709483
      0.001703617 0.000235941 0.000119783
    ]
  }
  controller "<extern>"
  supervisor TRUE
}
